ERROR 2024-12-09 06:17:18,154 log Internal Server Error: /api/group/get-customgroup-viewset-pagelist/
Traceback (most recent call last):
  File "/home/iboon_laptop_18/AI/imagelens/face_env/lib/python3.10/site-packages/django/core/handlers/exception.py", line 55, in inner
    response = get_response(request)
  File "/home/iboon_laptop_18/AI/imagelens/face_env/lib/python3.10/site-packages/django/core/handlers/base.py", line 197, in _get_response
    response = wrapped_callback(request, *callback_args, **callback_kwargs)
  File "/home/iboon_laptop_18/AI/imagelens/face_env/lib/python3.10/site-packages/django/views/decorators/csrf.py", line 65, in _view_wrapper
    return view_func(request, *args, **kwargs)
  File "/home/iboon_laptop_18/AI/imagelens/face_env/lib/python3.10/site-packages/rest_framework/viewsets.py", line 124, in view
    return self.dispatch(request, *args, **kwargs)
  File "/home/iboon_laptop_18/AI/imagelens/face_env/lib/python3.10/site-packages/rest_framework/views.py", line 509, in dispatch
    response = self.handle_exception(exc)
  File "/home/iboon_laptop_18/AI/imagelens/face_env/lib/python3.10/site-packages/rest_framework/views.py", line 469, in handle_exception
    self.raise_uncaught_exception(exc)
  File "/home/iboon_laptop_18/AI/imagelens/face_env/lib/python3.10/site-packages/rest_framework/views.py", line 480, in raise_uncaught_exception
    raise exc
  File "/home/iboon_laptop_18/AI/imagelens/face_env/lib/python3.10/site-packages/rest_framework/views.py", line 506, in dispatch
    response = handler(request, *args, **kwargs)
  File "/home/iboon_laptop_18/Documents/imagelens/groups/view/group_views.py", line 67, in list_page
    queryset = queryset.annotate(last_modified=Coalesce('updated_at', 'created_at')).order_by('-last_modified')
NameError: name 'Coalesce' is not defined
ERROR 2024-12-09 06:17:18,155 basehttp "GET /api/group/get-customgroup-viewset-pagelist/ HTTP/1.1" 500 100400
ERROR 2024-12-09 06:34:33,928 log Internal Server Error: /api/group/confirm-OTP-viewset/
Traceback (most recent call last):
  File "/home/iboon_laptop_18/AI/imagelens/face_env/lib/python3.10/site-packages/django/core/handlers/exception.py", line 55, in inner
    response = get_response(request)
  File "/home/iboon_laptop_18/AI/imagelens/face_env/lib/python3.10/site-packages/django/core/handlers/base.py", line 197, in _get_response
    response = wrapped_callback(request, *callback_args, **callback_kwargs)
  File "/home/iboon_laptop_18/AI/imagelens/face_env/lib/python3.10/site-packages/django/views/decorators/csrf.py", line 65, in _view_wrapper
    return view_func(request, *args, **kwargs)
  File "/home/iboon_laptop_18/AI/imagelens/face_env/lib/python3.10/site-packages/rest_framework/viewsets.py", line 124, in view
    return self.dispatch(request, *args, **kwargs)
  File "/home/iboon_laptop_18/AI/imagelens/face_env/lib/python3.10/site-packages/rest_framework/views.py", line 509, in dispatch
    response = self.handle_exception(exc)
  File "/home/iboon_laptop_18/AI/imagelens/face_env/lib/python3.10/site-packages/rest_framework/views.py", line 469, in handle_exception
    self.raise_uncaught_exception(exc)
  File "/home/iboon_laptop_18/AI/imagelens/face_env/lib/python3.10/site-packages/rest_framework/views.py", line 480, in raise_uncaught_exception
    raise exc
  File "/home/iboon_laptop_18/AI/imagelens/face_env/lib/python3.10/site-packages/rest_framework/views.py", line 506, in dispatch
    response = handler(request, *args, **kwargs)
  File "/home/iboon_laptop_18/Documents/imagelens/groups/view/group_views.py", line 473, in user_confirm
    users=get_user_model().objects.get(phone_no=mobile_number)
  File "/home/iboon_laptop_18/AI/imagelens/face_env/lib/python3.10/site-packages/django/db/models/manager.py", line 87, in manager_method
    return getattr(self.get_queryset(), name)(*args, **kwargs)
  File "/home/iboon_laptop_18/AI/imagelens/face_env/lib/python3.10/site-packages/django/db/models/query.py", line 649, in get
    raise self.model.DoesNotExist(
imagesense.models.User.DoesNotExist: User matching query does not exist.
ERROR 2024-12-09 06:34:33,929 basehttp "POST /api/group/confirm-OTP-viewset/ HTTP/1.1" 500 109409
ERROR 2024-12-09 06:35:04,132 log Internal Server Error: /api/group/confirm-OTP-viewset/
Traceback (most recent call last):
  File "/home/iboon_laptop_18/AI/imagelens/face_env/lib/python3.10/site-packages/django/core/handlers/exception.py", line 55, in inner
    response = get_response(request)
  File "/home/iboon_laptop_18/AI/imagelens/face_env/lib/python3.10/site-packages/django/core/handlers/base.py", line 197, in _get_response
    response = wrapped_callback(request, *callback_args, **callback_kwargs)
  File "/home/iboon_laptop_18/AI/imagelens/face_env/lib/python3.10/site-packages/django/views/decorators/csrf.py", line 65, in _view_wrapper
    return view_func(request, *args, **kwargs)
  File "/home/iboon_laptop_18/AI/imagelens/face_env/lib/python3.10/site-packages/rest_framework/viewsets.py", line 124, in view
    return self.dispatch(request, *args, **kwargs)
  File "/home/iboon_laptop_18/AI/imagelens/face_env/lib/python3.10/site-packages/rest_framework/views.py", line 509, in dispatch
    response = self.handle_exception(exc)
  File "/home/iboon_laptop_18/AI/imagelens/face_env/lib/python3.10/site-packages/rest_framework/views.py", line 469, in handle_exception
    self.raise_uncaught_exception(exc)
  File "/home/iboon_laptop_18/AI/imagelens/face_env/lib/python3.10/site-packages/rest_framework/views.py", line 480, in raise_uncaught_exception
    raise exc
  File "/home/iboon_laptop_18/AI/imagelens/face_env/lib/python3.10/site-packages/rest_framework/views.py", line 506, in dispatch
    response = handler(request, *args, **kwargs)
  File "/home/iboon_laptop_18/Documents/imagelens/groups/view/group_views.py", line 473, in user_confirm
    users=get_user_model().objects.get(phone_no=mobile_number)
  File "/home/iboon_laptop_18/AI/imagelens/face_env/lib/python3.10/site-packages/django/db/models/manager.py", line 87, in manager_method
    return getattr(self.get_queryset(), name)(*args, **kwargs)
  File "/home/iboon_laptop_18/AI/imagelens/face_env/lib/python3.10/site-packages/django/db/models/query.py", line 649, in get
    raise self.model.DoesNotExist(
imagesense.models.User.DoesNotExist: User matching query does not exist.
ERROR 2024-12-09 06:35:04,133 basehttp "POST /api/group/confirm-OTP-viewset/ HTTP/1.1" 500 109405
ERROR 2024-12-09 06:44:24,457 log Internal Server Error: /api/group/confirm-OTP-viewset/
Traceback (most recent call last):
  File "/home/iboon_laptop_18/AI/imagelens/face_env/lib/python3.10/site-packages/django/core/handlers/exception.py", line 55, in inner
    response = get_response(request)
  File "/home/iboon_laptop_18/AI/imagelens/face_env/lib/python3.10/site-packages/django/core/handlers/base.py", line 197, in _get_response
    response = wrapped_callback(request, *callback_args, **callback_kwargs)
  File "/home/iboon_laptop_18/AI/imagelens/face_env/lib/python3.10/site-packages/django/views/decorators/csrf.py", line 65, in _view_wrapper
    return view_func(request, *args, **kwargs)
  File "/home/iboon_laptop_18/AI/imagelens/face_env/lib/python3.10/site-packages/rest_framework/viewsets.py", line 124, in view
    return self.dispatch(request, *args, **kwargs)
  File "/home/iboon_laptop_18/AI/imagelens/face_env/lib/python3.10/site-packages/rest_framework/views.py", line 509, in dispatch
    response = self.handle_exception(exc)
  File "/home/iboon_laptop_18/AI/imagelens/face_env/lib/python3.10/site-packages/rest_framework/views.py", line 469, in handle_exception
    self.raise_uncaught_exception(exc)
  File "/home/iboon_laptop_18/AI/imagelens/face_env/lib/python3.10/site-packages/rest_framework/views.py", line 480, in raise_uncaught_exception
    raise exc
  File "/home/iboon_laptop_18/AI/imagelens/face_env/lib/python3.10/site-packages/rest_framework/views.py", line 506, in dispatch
    response = handler(request, *args, **kwargs)
  File "/home/iboon_laptop_18/Documents/imagelens/groups/view/group_views.py", line 474, in user_confirm
    users=get_user_model().objects.get(phone_no=mobile_no)
  File "/home/iboon_laptop_18/AI/imagelens/face_env/lib/python3.10/site-packages/django/db/models/manager.py", line 87, in manager_method
    return getattr(self.get_queryset(), name)(*args, **kwargs)
  File "/home/iboon_laptop_18/AI/imagelens/face_env/lib/python3.10/site-packages/django/db/models/query.py", line 649, in get
    raise self.model.DoesNotExist(
imagesense.models.User.DoesNotExist: User matching query does not exist.
ERROR 2024-12-09 06:44:24,459 basehttp "POST /api/group/confirm-OTP-viewset/ HTTP/1.1" 500 109419
ERROR 2024-12-09 09:01:49,661 log Internal Server Error: /api/group/photo-group-viewset-pagelist/
Traceback (most recent call last):
  File "/home/iboon_laptop_18/AI/imagelens/face_env/lib/python3.10/site-packages/django/core/handlers/exception.py", line 55, in inner
    response = get_response(request)
  File "/home/iboon_laptop_18/AI/imagelens/face_env/lib/python3.10/site-packages/django/core/handlers/base.py", line 197, in _get_response
    response = wrapped_callback(request, *callback_args, **callback_kwargs)
  File "/home/iboon_laptop_18/AI/imagelens/face_env/lib/python3.10/site-packages/django/views/decorators/csrf.py", line 65, in _view_wrapper
    return view_func(request, *args, **kwargs)
  File "/home/iboon_laptop_18/AI/imagelens/face_env/lib/python3.10/site-packages/rest_framework/viewsets.py", line 124, in view
    return self.dispatch(request, *args, **kwargs)
  File "/home/iboon_laptop_18/AI/imagelens/face_env/lib/python3.10/site-packages/rest_framework/views.py", line 509, in dispatch
    response = self.handle_exception(exc)
  File "/home/iboon_laptop_18/AI/imagelens/face_env/lib/python3.10/site-packages/rest_framework/views.py", line 469, in handle_exception
    self.raise_uncaught_exception(exc)
  File "/home/iboon_laptop_18/AI/imagelens/face_env/lib/python3.10/site-packages/rest_framework/views.py", line 480, in raise_uncaught_exception
    raise exc
  File "/home/iboon_laptop_18/AI/imagelens/face_env/lib/python3.10/site-packages/rest_framework/views.py", line 506, in dispatch
    response = handler(request, *args, **kwargs)
  File "/home/iboon_laptop_18/Documents/imagelens/groups/view/upload_photo_view.py", line 152, in list_page
    queryset = queryset.annotate(last_modified=Coalesce('updated_at', 'created_at')).order_by('-last_modified')
NameError: name 'Coalesce' is not defined
ERROR 2024-12-09 09:01:49,662 basehttp "GET /api/group/photo-group-viewset-pagelist/ HTTP/1.1" 500 100955
ERROR 2024-12-09 12:06:22,501 log Internal Server Error: /admin/
Traceback (most recent call last):
  File "/home/iboon_laptop_18/AI/imagelens/face_env/lib/python3.10/site-packages/django/core/handlers/exception.py", line 55, in inner
    response = get_response(request)
  File "/home/iboon_laptop_18/AI/imagelens/face_env/lib/python3.10/site-packages/django/core/handlers/base.py", line 220, in _get_response
    response = response.render()
  File "/home/iboon_laptop_18/AI/imagelens/face_env/lib/python3.10/site-packages/django/template/response.py", line 114, in render
    self.content = self.rendered_content
  File "/home/iboon_laptop_18/AI/imagelens/face_env/lib/python3.10/site-packages/django/template/response.py", line 92, in rendered_content
    return template.render(context, self._request)
  File "/home/iboon_laptop_18/AI/imagelens/face_env/lib/python3.10/site-packages/django/template/backends/django.py", line 107, in render
    return self.template.render(context)
  File "/home/iboon_laptop_18/AI/imagelens/face_env/lib/python3.10/site-packages/django/template/base.py", line 171, in render
    return self._render(context)
  File "/home/iboon_laptop_18/AI/imagelens/face_env/lib/python3.10/site-packages/django/template/base.py", line 163, in _render
    return self.nodelist.render(context)
  File "/home/iboon_laptop_18/AI/imagelens/face_env/lib/python3.10/site-packages/django/template/base.py", line 1008, in render
    return SafeString("".join([node.render_annotated(context) for node in self]))
  File "/home/iboon_laptop_18/AI/imagelens/face_env/lib/python3.10/site-packages/django/template/base.py", line 1008, in <listcomp>
    return SafeString("".join([node.render_annotated(context) for node in self]))
  File "/home/iboon_laptop_18/AI/imagelens/face_env/lib/python3.10/site-packages/django/template/base.py", line 969, in render_annotated
    return self.render(context)
  File "/home/iboon_laptop_18/AI/imagelens/face_env/lib/python3.10/site-packages/django/template/loader_tags.py", line 159, in render
    return compiled_parent._render(context)
  File "/home/iboon_laptop_18/AI/imagelens/face_env/lib/python3.10/site-packages/django/template/base.py", line 163, in _render
    return self.nodelist.render(context)
  File "/home/iboon_laptop_18/AI/imagelens/face_env/lib/python3.10/site-packages/django/template/base.py", line 1008, in render
    return SafeString("".join([node.render_annotated(context) for node in self]))
  File "/home/iboon_laptop_18/AI/imagelens/face_env/lib/python3.10/site-packages/django/template/base.py", line 1008, in <listcomp>
    return SafeString("".join([node.render_annotated(context) for node in self]))
  File "/home/iboon_laptop_18/AI/imagelens/face_env/lib/python3.10/site-packages/django/template/base.py", line 969, in render_annotated
    return self.render(context)
  File "/home/iboon_laptop_18/AI/imagelens/face_env/lib/python3.10/site-packages/django/template/loader_tags.py", line 159, in render
    return compiled_parent._render(context)
  File "/home/iboon_laptop_18/AI/imagelens/face_env/lib/python3.10/site-packages/django/template/base.py", line 163, in _render
    return self.nodelist.render(context)
  File "/home/iboon_laptop_18/AI/imagelens/face_env/lib/python3.10/site-packages/django/template/base.py", line 1008, in render
    return SafeString("".join([node.render_annotated(context) for node in self]))
  File "/home/iboon_laptop_18/AI/imagelens/face_env/lib/python3.10/site-packages/django/template/base.py", line 1008, in <listcomp>
    return SafeString("".join([node.render_annotated(context) for node in self]))
  File "/home/iboon_laptop_18/AI/imagelens/face_env/lib/python3.10/site-packages/django/template/base.py", line 969, in render_annotated
    return self.render(context)
  File "/home/iboon_laptop_18/AI/imagelens/face_env/lib/python3.10/site-packages/django/template/loader_tags.py", line 65, in render
    result = block.nodelist.render(context)
  File "/home/iboon_laptop_18/AI/imagelens/face_env/lib/python3.10/site-packages/django/template/base.py", line 1008, in render
    return SafeString("".join([node.render_annotated(context) for node in self]))
  File "/home/iboon_laptop_18/AI/imagelens/face_env/lib/python3.10/site-packages/django/template/base.py", line 1008, in <listcomp>
    return SafeString("".join([node.render_annotated(context) for node in self]))
  File "/home/iboon_laptop_18/AI/imagelens/face_env/lib/python3.10/site-packages/django/template/base.py", line 969, in render_annotated
    return self.render(context)
  File "/home/iboon_laptop_18/AI/imagelens/face_env/lib/python3.10/site-packages/django/templatetags/static.py", line 116, in render
    url = self.url(context)
  File "/home/iboon_laptop_18/AI/imagelens/face_env/lib/python3.10/site-packages/django/templatetags/static.py", line 113, in url
    return self.handle_simple(path)
  File "/home/iboon_laptop_18/AI/imagelens/face_env/lib/python3.10/site-packages/django/templatetags/static.py", line 129, in handle_simple
    return staticfiles_storage.url(path)
  File "/home/iboon_laptop_18/AI/imagelens/face_env/lib/python3.10/site-packages/storages/backends/s3.py", line 690, in url
    params["Bucket"] = self.bucket.name
  File "/home/iboon_laptop_18/AI/imagelens/face_env/lib/python3.10/site-packages/storages/backends/s3.py", line 514, in bucket
    self._bucket = self.connection.Bucket(self.bucket_name)
  File "/home/iboon_laptop_18/AI/imagelens/face_env/lib/python3.10/site-packages/boto3/resources/factory.py", line 528, in create_resource
    return partial(
  File "/home/iboon_laptop_18/AI/imagelens/face_env/lib/python3.10/site-packages/boto3/resources/base.py", line 123, in __init__
    raise ValueError(f'Required parameter {identifier} not set')
ValueError: Required parameter name not set
ERROR 2024-12-09 12:06:22,502 basehttp "GET /admin/ HTTP/1.1" 500 381228
ERROR 2024-12-09 12:06:23,578 log Internal Server Error: /admin/
Traceback (most recent call last):
  File "/home/iboon_laptop_18/AI/imagelens/face_env/lib/python3.10/site-packages/django/core/handlers/exception.py", line 55, in inner
    response = get_response(request)
  File "/home/iboon_laptop_18/AI/imagelens/face_env/lib/python3.10/site-packages/django/core/handlers/base.py", line 220, in _get_response
    response = response.render()
  File "/home/iboon_laptop_18/AI/imagelens/face_env/lib/python3.10/site-packages/django/template/response.py", line 114, in render
    self.content = self.rendered_content
  File "/home/iboon_laptop_18/AI/imagelens/face_env/lib/python3.10/site-packages/django/template/response.py", line 92, in rendered_content
    return template.render(context, self._request)
  File "/home/iboon_laptop_18/AI/imagelens/face_env/lib/python3.10/site-packages/django/template/backends/django.py", line 107, in render
    return self.template.render(context)
  File "/home/iboon_laptop_18/AI/imagelens/face_env/lib/python3.10/site-packages/django/template/base.py", line 171, in render
    return self._render(context)
  File "/home/iboon_laptop_18/AI/imagelens/face_env/lib/python3.10/site-packages/django/template/base.py", line 163, in _render
    return self.nodelist.render(context)
  File "/home/iboon_laptop_18/AI/imagelens/face_env/lib/python3.10/site-packages/django/template/base.py", line 1008, in render
    return SafeString("".join([node.render_annotated(context) for node in self]))
  File "/home/iboon_laptop_18/AI/imagelens/face_env/lib/python3.10/site-packages/django/template/base.py", line 1008, in <listcomp>
    return SafeString("".join([node.render_annotated(context) for node in self]))
  File "/home/iboon_laptop_18/AI/imagelens/face_env/lib/python3.10/site-packages/django/template/base.py", line 969, in render_annotated
    return self.render(context)
  File "/home/iboon_laptop_18/AI/imagelens/face_env/lib/python3.10/site-packages/django/template/loader_tags.py", line 159, in render
    return compiled_parent._render(context)
  File "/home/iboon_laptop_18/AI/imagelens/face_env/lib/python3.10/site-packages/django/template/base.py", line 163, in _render
    return self.nodelist.render(context)
  File "/home/iboon_laptop_18/AI/imagelens/face_env/lib/python3.10/site-packages/django/template/base.py", line 1008, in render
    return SafeString("".join([node.render_annotated(context) for node in self]))
  File "/home/iboon_laptop_18/AI/imagelens/face_env/lib/python3.10/site-packages/django/template/base.py", line 1008, in <listcomp>
    return SafeString("".join([node.render_annotated(context) for node in self]))
  File "/home/iboon_laptop_18/AI/imagelens/face_env/lib/python3.10/site-packages/django/template/base.py", line 969, in render_annotated
    return self.render(context)
  File "/home/iboon_laptop_18/AI/imagelens/face_env/lib/python3.10/site-packages/django/template/loader_tags.py", line 159, in render
    return compiled_parent._render(context)
  File "/home/iboon_laptop_18/AI/imagelens/face_env/lib/python3.10/site-packages/django/template/base.py", line 163, in _render
    return self.nodelist.render(context)
  File "/home/iboon_laptop_18/AI/imagelens/face_env/lib/python3.10/site-packages/django/template/base.py", line 1008, in render
    return SafeString("".join([node.render_annotated(context) for node in self]))
  File "/home/iboon_laptop_18/AI/imagelens/face_env/lib/python3.10/site-packages/django/template/base.py", line 1008, in <listcomp>
    return SafeString("".join([node.render_annotated(context) for node in self]))
  File "/home/iboon_laptop_18/AI/imagelens/face_env/lib/python3.10/site-packages/django/template/base.py", line 969, in render_annotated
    return self.render(context)
  File "/home/iboon_laptop_18/AI/imagelens/face_env/lib/python3.10/site-packages/django/template/loader_tags.py", line 65, in render
    result = block.nodelist.render(context)
  File "/home/iboon_laptop_18/AI/imagelens/face_env/lib/python3.10/site-packages/django/template/base.py", line 1008, in render
    return SafeString("".join([node.render_annotated(context) for node in self]))
  File "/home/iboon_laptop_18/AI/imagelens/face_env/lib/python3.10/site-packages/django/template/base.py", line 1008, in <listcomp>
    return SafeString("".join([node.render_annotated(context) for node in self]))
  File "/home/iboon_laptop_18/AI/imagelens/face_env/lib/python3.10/site-packages/django/template/base.py", line 969, in render_annotated
    return self.render(context)
  File "/home/iboon_laptop_18/AI/imagelens/face_env/lib/python3.10/site-packages/django/templatetags/static.py", line 116, in render
    url = self.url(context)
  File "/home/iboon_laptop_18/AI/imagelens/face_env/lib/python3.10/site-packages/django/templatetags/static.py", line 113, in url
    return self.handle_simple(path)
  File "/home/iboon_laptop_18/AI/imagelens/face_env/lib/python3.10/site-packages/django/templatetags/static.py", line 129, in handle_simple
    return staticfiles_storage.url(path)
  File "/home/iboon_laptop_18/AI/imagelens/face_env/lib/python3.10/site-packages/storages/backends/s3.py", line 690, in url
    params["Bucket"] = self.bucket.name
  File "/home/iboon_laptop_18/AI/imagelens/face_env/lib/python3.10/site-packages/storages/backends/s3.py", line 514, in bucket
    self._bucket = self.connection.Bucket(self.bucket_name)
  File "/home/iboon_laptop_18/AI/imagelens/face_env/lib/python3.10/site-packages/boto3/resources/factory.py", line 528, in create_resource
    return partial(
  File "/home/iboon_laptop_18/AI/imagelens/face_env/lib/python3.10/site-packages/boto3/resources/base.py", line 123, in __init__
    raise ValueError(f'Required parameter {identifier} not set')
ValueError: Required parameter name not set
ERROR 2024-12-09 12:06:23,578 basehttp "GET /admin/ HTTP/1.1" 500 381228
ERROR 2024-12-10 08:48:17,453 log Internal Server Error: /api/group/upload-group-image-download_image/945/
Traceback (most recent call last):
  File "/home/iboon_laptop_18/AI/imagelens/face_env/lib/python3.10/site-packages/django/core/handlers/exception.py", line 55, in inner
    response = get_response(request)
  File "/home/iboon_laptop_18/AI/imagelens/face_env/lib/python3.10/site-packages/django/core/handlers/base.py", line 197, in _get_response
    response = wrapped_callback(request, *callback_args, **callback_kwargs)
  File "/home/iboon_laptop_18/AI/imagelens/face_env/lib/python3.10/site-packages/django/views/decorators/csrf.py", line 65, in _view_wrapper
    return view_func(request, *args, **kwargs)
  File "/home/iboon_laptop_18/AI/imagelens/face_env/lib/python3.10/site-packages/rest_framework/viewsets.py", line 124, in view
    return self.dispatch(request, *args, **kwargs)
  File "/home/iboon_laptop_18/AI/imagelens/face_env/lib/python3.10/site-packages/rest_framework/views.py", line 509, in dispatch
    response = self.handle_exception(exc)
  File "/home/iboon_laptop_18/AI/imagelens/face_env/lib/python3.10/site-packages/rest_framework/views.py", line 469, in handle_exception
    self.raise_uncaught_exception(exc)
  File "/home/iboon_laptop_18/AI/imagelens/face_env/lib/python3.10/site-packages/rest_framework/views.py", line 480, in raise_uncaught_exception
    raise exc
  File "/home/iboon_laptop_18/AI/imagelens/face_env/lib/python3.10/site-packages/rest_framework/views.py", line 506, in dispatch
    response = handler(request, *args, **kwargs)
  File "/home/iboon_laptop_18/Documents/imagelens/groups/view/upload_photo_view.py", line 440, in download_image
    file_path = photo_image.image2.path
  File "/home/iboon_laptop_18/AI/imagelens/face_env/lib/python3.10/site-packages/django/db/models/fields/files.py", line 65, in path
    return self.storage.path(self.name)
  File "/home/iboon_laptop_18/AI/imagelens/face_env/lib/python3.10/site-packages/django/core/files/storage/base.py", line 137, in path
    raise NotImplementedError("This backend doesn't support absolute paths.")
NotImplementedError: This backend doesn't support absolute paths.
ERROR 2024-12-10 08:48:17,454 basehttp "GET /api/group/upload-group-image-download_image/945/ HTTP/1.1" 500 108170
ERROR 2024-12-10 09:08:19,852 log Internal Server Error: /api/group/upload-group-image-download_image/945/
Traceback (most recent call last):
  File "/home/iboon_laptop_18/AI/imagelens/face_env/lib/python3.10/site-packages/django/core/handlers/exception.py", line 55, in inner
    response = get_response(request)
  File "/home/iboon_laptop_18/AI/imagelens/face_env/lib/python3.10/site-packages/django/core/handlers/base.py", line 197, in _get_response
    response = wrapped_callback(request, *callback_args, **callback_kwargs)
  File "/home/iboon_laptop_18/AI/imagelens/face_env/lib/python3.10/site-packages/django/views/decorators/csrf.py", line 65, in _view_wrapper
    return view_func(request, *args, **kwargs)
  File "/home/iboon_laptop_18/AI/imagelens/face_env/lib/python3.10/site-packages/rest_framework/viewsets.py", line 124, in view
    return self.dispatch(request, *args, **kwargs)
  File "/home/iboon_laptop_18/AI/imagelens/face_env/lib/python3.10/site-packages/rest_framework/views.py", line 509, in dispatch
    response = self.handle_exception(exc)
  File "/home/iboon_laptop_18/AI/imagelens/face_env/lib/python3.10/site-packages/rest_framework/views.py", line 469, in handle_exception
    self.raise_uncaught_exception(exc)
  File "/home/iboon_laptop_18/AI/imagelens/face_env/lib/python3.10/site-packages/rest_framework/views.py", line 480, in raise_uncaught_exception
    raise exc
  File "/home/iboon_laptop_18/AI/imagelens/face_env/lib/python3.10/site-packages/rest_framework/views.py", line 506, in dispatch
    response = handler(request, *args, **kwargs)
  File "/home/iboon_laptop_18/Documents/imagelens/groups/view/upload_photo_view.py", line 441, in download_image
    status=status.HTTP_404_NOT_FOUND
  File "/home/iboon_laptop_18/AI/imagelens/face_env/lib/python3.10/site-packages/django/http/response.py", line 376, in __init__
    self.content = content
  File "/home/iboon_laptop_18/AI/imagelens/face_env/lib/python3.10/site-packages/django/http/response.py", line 401, in content
    content = b"".join(self.make_bytes(chunk) for chunk in value)
  File "/home/iboon_laptop_18/AI/imagelens/face_env/lib/python3.10/site-packages/django/http/response.py", line 401, in <genexpr>
    content = b"".join(self.make_bytes(chunk) for chunk in value)
  File "/home/iboon_laptop_18/AI/imagelens/face_env/lib/python3.10/site-packages/django/core/files/base.py", line 78, in __iter__
    for chunk in self.chunks():
  File "/home/iboon_laptop_18/AI/imagelens/face_env/lib/python3.10/site-packages/django/core/files/base.py", line 55, in chunks
    self.seek(0)
  File "/home/iboon_laptop_18/AI/imagelens/face_env/lib/python3.10/site-packages/django/core/files/utils.py", line 45, in <lambda>
    seek = property(lambda self: self.file.seek)
  File "/home/iboon_laptop_18/AI/imagelens/face_env/lib/python3.10/site-packages/django/core/files/utils.py", line 45, in <lambda>
    seek = property(lambda self: self.file.seek)
  File "/home/iboon_laptop_18/AI/imagelens/face_env/lib/python3.10/site-packages/storages/backends/s3.py", line 179, in _get_file
    self.obj.download_fileobj(
  File "/home/iboon_laptop_18/AI/imagelens/face_env/lib/python3.10/site-packages/boto3/s3/inject.py", line 890, in object_download_fileobj
    return self.meta.client.download_fileobj(
  File "/home/iboon_laptop_18/AI/imagelens/face_env/lib/python3.10/site-packages/boto3/s3/inject.py", line 794, in download_fileobj
    future = manager.download(
  File "/home/iboon_laptop_18/AI/imagelens/face_env/lib/python3.10/site-packages/s3transfer/manager.py", line 383, in download
    return self._submit_transfer(
  File "/home/iboon_laptop_18/AI/imagelens/face_env/lib/python3.10/site-packages/s3transfer/manager.py", line 533, in _submit_transfer
    self._submission_executor.submit(
  File "/home/iboon_laptop_18/AI/imagelens/face_env/lib/python3.10/site-packages/s3transfer/futures.py", line 470, in submit
    future = ExecutorFuture(self._executor.submit(task))
  File "/usr/lib/python3.10/concurrent/futures/thread.py", line 169, in submit
    raise RuntimeError('cannot schedule new futures after '
RuntimeError: cannot schedule new futures after interpreter shutdown
ERROR 2024-12-10 09:08:19,854 basehttp "GET /api/group/upload-group-image-download_image/945/ HTTP/1.1" 500 162702
ERROR 2024-12-10 09:56:10,707 log Internal Server Error: /api/group/create-customgroupmember-viewset/
Traceback (most recent call last):
  File "/home/iboon_laptop_18/AI/imagelens/face_env/lib/python3.10/site-packages/django/core/handlers/exception.py", line 55, in inner
    response = get_response(request)
  File "/home/iboon_laptop_18/AI/imagelens/face_env/lib/python3.10/site-packages/django/core/handlers/base.py", line 197, in _get_response
    response = wrapped_callback(request, *callback_args, **callback_kwargs)
  File "/home/iboon_laptop_18/AI/imagelens/face_env/lib/python3.10/site-packages/django/views/decorators/csrf.py", line 65, in _view_wrapper
    return view_func(request, *args, **kwargs)
  File "/home/iboon_laptop_18/AI/imagelens/face_env/lib/python3.10/site-packages/rest_framework/viewsets.py", line 124, in view
    return self.dispatch(request, *args, **kwargs)
  File "/home/iboon_laptop_18/AI/imagelens/face_env/lib/python3.10/site-packages/rest_framework/views.py", line 509, in dispatch
    response = self.handle_exception(exc)
  File "/home/iboon_laptop_18/AI/imagelens/face_env/lib/python3.10/site-packages/rest_framework/views.py", line 469, in handle_exception
    self.raise_uncaught_exception(exc)
  File "/home/iboon_laptop_18/AI/imagelens/face_env/lib/python3.10/site-packages/rest_framework/views.py", line 480, in raise_uncaught_exception
    raise exc
  File "/home/iboon_laptop_18/AI/imagelens/face_env/lib/python3.10/site-packages/rest_framework/views.py", line 506, in dispatch
    response = handler(request, *args, **kwargs)
  File "/home/iboon_laptop_18/Documents/imagelens/groups/view/group_views.py", line 613, in join
    {"status":True,"data": serializer.data},
  File "/home/iboon_laptop_18/AI/imagelens/face_env/lib/python3.10/site-packages/rest_framework/serializers.py", line 571, in data
    ret = super().data
  File "/home/iboon_laptop_18/AI/imagelens/face_env/lib/python3.10/site-packages/rest_framework/serializers.py", line 249, in data
    self._data = self.to_representation(self.instance)
  File "/home/iboon_laptop_18/AI/imagelens/face_env/lib/python3.10/site-packages/rest_framework/serializers.py", line 523, in to_representation
    for field in fields:
  File "/home/iboon_laptop_18/AI/imagelens/face_env/lib/python3.10/site-packages/rest_framework/serializers.py", line 384, in _readable_fields
    for field in self.fields.values():
  File "/home/iboon_laptop_18/AI/imagelens/face_env/lib/python3.10/site-packages/django/utils/functional.py", line 47, in __get__
    res = instance.__dict__[self.name] = self.func(instance)
  File "/home/iboon_laptop_18/AI/imagelens/face_env/lib/python3.10/site-packages/rest_framework/serializers.py", line 372, in fields
    for key, value in self.get_fields().items():
  File "/home/iboon_laptop_18/AI/imagelens/face_env/lib/python3.10/site-packages/rest_framework/serializers.py", line 1103, in get_fields
    field_class, field_kwargs = self.build_field(
  File "/home/iboon_laptop_18/AI/imagelens/face_env/lib/python3.10/site-packages/rest_framework/serializers.py", line 1249, in build_field
    return self.build_unknown_field(field_name, model_class)
  File "/home/iboon_laptop_18/AI/imagelens/face_env/lib/python3.10/site-packages/rest_framework/serializers.py", line 1367, in build_unknown_field
    raise ImproperlyConfigured(
django.core.exceptions.ImproperlyConfigured: Field name `created_at` is not valid for model `GroupMember` in `groups.serializers.group_serializers.GroupMemberSerializer`.
ERROR 2024-12-10 09:56:10,730 basehttp "POST /api/group/create-customgroupmember-viewset/ HTTP/1.1" 500 147043
ERROR 2024-12-10 09:58:38,383 log Internal Server Error: /api/group/create-customgroupmember-viewset/
Traceback (most recent call last):
  File "/home/iboon_laptop_18/AI/imagelens/face_env/lib/python3.10/site-packages/django/core/handlers/exception.py", line 55, in inner
    response = get_response(request)
  File "/home/iboon_laptop_18/AI/imagelens/face_env/lib/python3.10/site-packages/django/core/handlers/base.py", line 197, in _get_response
    response = wrapped_callback(request, *callback_args, **callback_kwargs)
  File "/home/iboon_laptop_18/AI/imagelens/face_env/lib/python3.10/site-packages/django/views/decorators/csrf.py", line 65, in _view_wrapper
    return view_func(request, *args, **kwargs)
  File "/home/iboon_laptop_18/AI/imagelens/face_env/lib/python3.10/site-packages/rest_framework/viewsets.py", line 124, in view
    return self.dispatch(request, *args, **kwargs)
  File "/home/iboon_laptop_18/AI/imagelens/face_env/lib/python3.10/site-packages/rest_framework/views.py", line 509, in dispatch
    response = self.handle_exception(exc)
  File "/home/iboon_laptop_18/AI/imagelens/face_env/lib/python3.10/site-packages/rest_framework/views.py", line 469, in handle_exception
    self.raise_uncaught_exception(exc)
  File "/home/iboon_laptop_18/AI/imagelens/face_env/lib/python3.10/site-packages/rest_framework/views.py", line 480, in raise_uncaught_exception
    raise exc
  File "/home/iboon_laptop_18/AI/imagelens/face_env/lib/python3.10/site-packages/rest_framework/views.py", line 506, in dispatch
    response = handler(request, *args, **kwargs)
  File "/home/iboon_laptop_18/Documents/imagelens/groups/view/group_views.py", line 613, in join
    {"status":True,"data": serializer.data},
  File "/home/iboon_laptop_18/AI/imagelens/face_env/lib/python3.10/site-packages/rest_framework/serializers.py", line 571, in data
    ret = super().data
  File "/home/iboon_laptop_18/AI/imagelens/face_env/lib/python3.10/site-packages/rest_framework/serializers.py", line 249, in data
    self._data = self.to_representation(self.instance)
  File "/home/iboon_laptop_18/AI/imagelens/face_env/lib/python3.10/site-packages/rest_framework/serializers.py", line 523, in to_representation
    for field in fields:
  File "/home/iboon_laptop_18/AI/imagelens/face_env/lib/python3.10/site-packages/rest_framework/serializers.py", line 384, in _readable_fields
    for field in self.fields.values():
  File "/home/iboon_laptop_18/AI/imagelens/face_env/lib/python3.10/site-packages/django/utils/functional.py", line 47, in __get__
    res = instance.__dict__[self.name] = self.func(instance)
  File "/home/iboon_laptop_18/AI/imagelens/face_env/lib/python3.10/site-packages/rest_framework/serializers.py", line 372, in fields
    for key, value in self.get_fields().items():
  File "/home/iboon_laptop_18/AI/imagelens/face_env/lib/python3.10/site-packages/rest_framework/serializers.py", line 1103, in get_fields
    field_class, field_kwargs = self.build_field(
  File "/home/iboon_laptop_18/AI/imagelens/face_env/lib/python3.10/site-packages/rest_framework/serializers.py", line 1249, in build_field
    return self.build_unknown_field(field_name, model_class)
  File "/home/iboon_laptop_18/AI/imagelens/face_env/lib/python3.10/site-packages/rest_framework/serializers.py", line 1367, in build_unknown_field
    raise ImproperlyConfigured(
django.core.exceptions.ImproperlyConfigured: Field name `created_at__id` is not valid for model `GroupMember` in `groups.serializers.group_serializers.GroupMemberSerializer`.
ERROR 2024-12-10 09:58:38,400 basehttp "POST /api/group/create-customgroupmember-viewset/ HTTP/1.1" 500 147127
ERROR 2024-12-10 10:35:10,303 log Internal Server Error: /api/analyze-face-image/
ERROR 2024-12-10 10:35:10,304 basehttp "POST /api/analyze-face-image/ HTTP/1.1" 500 360
ERROR 2024-12-10 10:48:41,401 log Internal Server Error: /api/analyze-face-image/
ERROR 2024-12-10 10:48:41,401 basehttp "POST /api/analyze-face-image/ HTTP/1.1" 500 142
ERROR 2024-12-10 11:20:31,044 log Internal Server Error: /api/user/logout/
Traceback (most recent call last):
  File "/home/iboon_laptop_18/Documents/imagelens/imagesense/serializers.py", line 127, in save
    token = RefreshToken(self.refresh_token)
  File "/home/iboon_laptop_18/AI/imagelens/face_env/lib/python3.10/site-packages/rest_framework_simplejwt/tokens.py", line 61, in __init__
    self.verify()
  File "/home/iboon_laptop_18/AI/imagelens/face_env/lib/python3.10/site-packages/rest_framework_simplejwt/tokens.py", line 245, in verify
    self.check_blacklist()
  File "/home/iboon_laptop_18/AI/imagelens/face_env/lib/python3.10/site-packages/rest_framework_simplejwt/tokens.py", line 257, in check_blacklist
    raise TokenError(_("Token is blacklisted"))
rest_framework_simplejwt.exceptions.TokenError: Token is blacklisted

During handling of the above exception, another exception occurred:

Traceback (most recent call last):
  File "/home/iboon_laptop_18/AI/imagelens/face_env/lib/python3.10/site-packages/django/core/handlers/exception.py", line 55, in inner
    response = get_response(request)
  File "/home/iboon_laptop_18/AI/imagelens/face_env/lib/python3.10/site-packages/django/core/handlers/base.py", line 197, in _get_response
    response = wrapped_callback(request, *callback_args, **callback_kwargs)
  File "/home/iboon_laptop_18/AI/imagelens/face_env/lib/python3.10/site-packages/django/views/decorators/csrf.py", line 65, in _view_wrapper
    return view_func(request, *args, **kwargs)
  File "/home/iboon_laptop_18/AI/imagelens/face_env/lib/python3.10/site-packages/django/views/generic/base.py", line 104, in view
    return self.dispatch(request, *args, **kwargs)
  File "/home/iboon_laptop_18/AI/imagelens/face_env/lib/python3.10/site-packages/rest_framework/views.py", line 509, in dispatch
    response = self.handle_exception(exc)
  File "/home/iboon_laptop_18/AI/imagelens/face_env/lib/python3.10/site-packages/rest_framework/views.py", line 469, in handle_exception
    self.raise_uncaught_exception(exc)
  File "/home/iboon_laptop_18/AI/imagelens/face_env/lib/python3.10/site-packages/rest_framework/views.py", line 480, in raise_uncaught_exception
    raise exc
  File "/home/iboon_laptop_18/AI/imagelens/face_env/lib/python3.10/site-packages/rest_framework/views.py", line 506, in dispatch
    response = handler(request, *args, **kwargs)
  File "/home/iboon_laptop_18/Documents/imagelens/imagesense/views.py", line 208, in post
    serializer.save()
  File "/home/iboon_laptop_18/Documents/imagelens/imagesense/serializers.py", line 132, in save
    self.fail('bad_token')
  File "/home/iboon_laptop_18/AI/imagelens/face_env/lib/python3.10/site-packages/rest_framework/fields.py", line 600, in fail
    message_string = msg.format(**kwargs)
AttributeError: 'dict' object has no attribute 'format'
ERROR 2024-12-10 11:20:31,046 basehttp "POST /api/user/logout/ HTTP/1.1" 500 127767
ERROR 2024-12-10 11:20:31,964 log Internal Server Error: /api/user/logout/
Traceback (most recent call last):
  File "/home/iboon_laptop_18/Documents/imagelens/imagesense/serializers.py", line 127, in save
    token = RefreshToken(self.refresh_token)
  File "/home/iboon_laptop_18/AI/imagelens/face_env/lib/python3.10/site-packages/rest_framework_simplejwt/tokens.py", line 61, in __init__
    self.verify()
  File "/home/iboon_laptop_18/AI/imagelens/face_env/lib/python3.10/site-packages/rest_framework_simplejwt/tokens.py", line 245, in verify
    self.check_blacklist()
  File "/home/iboon_laptop_18/AI/imagelens/face_env/lib/python3.10/site-packages/rest_framework_simplejwt/tokens.py", line 257, in check_blacklist
    raise TokenError(_("Token is blacklisted"))
rest_framework_simplejwt.exceptions.TokenError: Token is blacklisted

During handling of the above exception, another exception occurred:

Traceback (most recent call last):
  File "/home/iboon_laptop_18/AI/imagelens/face_env/lib/python3.10/site-packages/django/core/handlers/exception.py", line 55, in inner
    response = get_response(request)
  File "/home/iboon_laptop_18/AI/imagelens/face_env/lib/python3.10/site-packages/django/core/handlers/base.py", line 197, in _get_response
    response = wrapped_callback(request, *callback_args, **callback_kwargs)
  File "/home/iboon_laptop_18/AI/imagelens/face_env/lib/python3.10/site-packages/django/views/decorators/csrf.py", line 65, in _view_wrapper
    return view_func(request, *args, **kwargs)
  File "/home/iboon_laptop_18/AI/imagelens/face_env/lib/python3.10/site-packages/django/views/generic/base.py", line 104, in view
    return self.dispatch(request, *args, **kwargs)
  File "/home/iboon_laptop_18/AI/imagelens/face_env/lib/python3.10/site-packages/rest_framework/views.py", line 509, in dispatch
    response = self.handle_exception(exc)
  File "/home/iboon_laptop_18/AI/imagelens/face_env/lib/python3.10/site-packages/rest_framework/views.py", line 469, in handle_exception
    self.raise_uncaught_exception(exc)
  File "/home/iboon_laptop_18/AI/imagelens/face_env/lib/python3.10/site-packages/rest_framework/views.py", line 480, in raise_uncaught_exception
    raise exc
  File "/home/iboon_laptop_18/AI/imagelens/face_env/lib/python3.10/site-packages/rest_framework/views.py", line 506, in dispatch
    response = handler(request, *args, **kwargs)
  File "/home/iboon_laptop_18/Documents/imagelens/imagesense/views.py", line 208, in post
    serializer.save()
  File "/home/iboon_laptop_18/Documents/imagelens/imagesense/serializers.py", line 132, in save
    self.fail('bad_token')
  File "/home/iboon_laptop_18/AI/imagelens/face_env/lib/python3.10/site-packages/rest_framework/fields.py", line 600, in fail
    message_string = msg.format(**kwargs)
AttributeError: 'dict' object has no attribute 'format'
ERROR 2024-12-10 11:20:31,964 basehttp "POST /api/user/logout/ HTTP/1.1" 500 127767
ERROR 2024-12-10 11:39:23,418 log Internal Server Error: /api/user/logout/
Traceback (most recent call last):
  File "/home/iboon_laptop_18/Documents/imagelens/imagesense/serializers.py", line 127, in save
    token = RefreshToken(self.refresh_token)
  File "/home/iboon_laptop_18/AI/imagelens/face_env/lib/python3.10/site-packages/rest_framework_simplejwt/tokens.py", line 61, in __init__
    self.verify()
  File "/home/iboon_laptop_18/AI/imagelens/face_env/lib/python3.10/site-packages/rest_framework_simplejwt/tokens.py", line 245, in verify
    self.check_blacklist()
  File "/home/iboon_laptop_18/AI/imagelens/face_env/lib/python3.10/site-packages/rest_framework_simplejwt/tokens.py", line 257, in check_blacklist
    raise TokenError(_("Token is blacklisted"))
rest_framework_simplejwt.exceptions.TokenError: Token is blacklisted

During handling of the above exception, another exception occurred:

Traceback (most recent call last):
  File "/home/iboon_laptop_18/AI/imagelens/face_env/lib/python3.10/site-packages/django/core/handlers/exception.py", line 55, in inner
    response = get_response(request)
  File "/home/iboon_laptop_18/AI/imagelens/face_env/lib/python3.10/site-packages/django/core/handlers/base.py", line 197, in _get_response
    response = wrapped_callback(request, *callback_args, **callback_kwargs)
  File "/home/iboon_laptop_18/AI/imagelens/face_env/lib/python3.10/site-packages/django/views/decorators/csrf.py", line 65, in _view_wrapper
    return view_func(request, *args, **kwargs)
  File "/home/iboon_laptop_18/AI/imagelens/face_env/lib/python3.10/site-packages/django/views/generic/base.py", line 104, in view
    return self.dispatch(request, *args, **kwargs)
  File "/home/iboon_laptop_18/AI/imagelens/face_env/lib/python3.10/site-packages/rest_framework/views.py", line 509, in dispatch
    response = self.handle_exception(exc)
  File "/home/iboon_laptop_18/AI/imagelens/face_env/lib/python3.10/site-packages/rest_framework/views.py", line 469, in handle_exception
    self.raise_uncaught_exception(exc)
  File "/home/iboon_laptop_18/AI/imagelens/face_env/lib/python3.10/site-packages/rest_framework/views.py", line 480, in raise_uncaught_exception
    raise exc
  File "/home/iboon_laptop_18/AI/imagelens/face_env/lib/python3.10/site-packages/rest_framework/views.py", line 506, in dispatch
    response = handler(request, *args, **kwargs)
  File "/home/iboon_laptop_18/Documents/imagelens/imagesense/views.py", line 208, in post
    serializer.save()
  File "/home/iboon_laptop_18/Documents/imagelens/imagesense/serializers.py", line 132, in save
    self.fail('bad_token')
  File "/home/iboon_laptop_18/AI/imagelens/face_env/lib/python3.10/site-packages/rest_framework/fields.py", line 600, in fail
    message_string = msg.format(**kwargs)
AttributeError: 'dict' object has no attribute 'format'
ERROR 2024-12-10 11:39:23,419 basehttp "POST /api/user/logout/ HTTP/1.1" 500 127767
ERROR 2024-12-11 00:45:56,306 log Internal Server Error: /api/group/group-list/17/
ERROR 2024-12-11 00:45:56,306 basehttp "POST /api/group/group-list/17/ HTTP/1.1" 500 81
ERROR 2024-12-11 15:52:37,284 log Internal Server Error: /api/group/get-customgroup-viewset-family-member/
Traceback (most recent call last):
  File "/home/iboon_laptop_18/AI/imagelens/face_env/lib/python3.10/site-packages/django/core/handlers/exception.py", line 55, in inner
    response = get_response(request)
  File "/home/iboon_laptop_18/AI/imagelens/face_env/lib/python3.10/site-packages/django/core/handlers/base.py", line 197, in _get_response
    response = wrapped_callback(request, *callback_args, **callback_kwargs)
  File "/home/iboon_laptop_18/AI/imagelens/face_env/lib/python3.10/site-packages/django/views/decorators/csrf.py", line 65, in _view_wrapper
    return view_func(request, *args, **kwargs)
  File "/home/iboon_laptop_18/AI/imagelens/face_env/lib/python3.10/site-packages/rest_framework/viewsets.py", line 124, in view
    return self.dispatch(request, *args, **kwargs)
  File "/home/iboon_laptop_18/AI/imagelens/face_env/lib/python3.10/site-packages/rest_framework/views.py", line 509, in dispatch
    response = self.handle_exception(exc)
  File "/home/iboon_laptop_18/AI/imagelens/face_env/lib/python3.10/site-packages/rest_framework/views.py", line 469, in handle_exception
    self.raise_uncaught_exception(exc)
  File "/home/iboon_laptop_18/AI/imagelens/face_env/lib/python3.10/site-packages/rest_framework/views.py", line 480, in raise_uncaught_exception
    raise exc
  File "/home/iboon_laptop_18/AI/imagelens/face_env/lib/python3.10/site-packages/rest_framework/views.py", line 506, in dispatch
    response = handler(request, *args, **kwargs)
  File "/home/iboon_laptop_18/Documents/imagelens/groups/view/group_views.py", line 36, in get_family_photos
    custom_group = self.get_object()
  File "/home/iboon_laptop_18/AI/imagelens/face_env/lib/python3.10/site-packages/rest_framework/generics.py", line 92, in get_object
    assert lookup_url_kwarg in self.kwargs, (
AssertionError: Expected view CustomGroupViewSet to be called with a URL keyword argument named "pk". Fix your URL conf, or set the `.lookup_field` attribute on the view correctly.
ERROR 2024-12-11 15:52:37,291 basehttp "GET /api/group/get-customgroup-viewset-family-member/ HTTP/1.1" 500 105363
ERROR 2024-12-11 15:53:10,043 log Internal Server Error: /api/group/get-customgroup-viewset-family-member/17/
Traceback (most recent call last):
  File "/home/iboon_laptop_18/AI/imagelens/face_env/lib/python3.10/site-packages/django/core/handlers/exception.py", line 55, in inner
    response = get_response(request)
  File "/home/iboon_laptop_18/AI/imagelens/face_env/lib/python3.10/site-packages/django/core/handlers/base.py", line 197, in _get_response
    response = wrapped_callback(request, *callback_args, **callback_kwargs)
  File "/home/iboon_laptop_18/AI/imagelens/face_env/lib/python3.10/site-packages/django/views/decorators/csrf.py", line 65, in _view_wrapper
    return view_func(request, *args, **kwargs)
  File "/home/iboon_laptop_18/AI/imagelens/face_env/lib/python3.10/site-packages/rest_framework/viewsets.py", line 124, in view
    return self.dispatch(request, *args, **kwargs)
  File "/home/iboon_laptop_18/AI/imagelens/face_env/lib/python3.10/site-packages/rest_framework/views.py", line 509, in dispatch
    response = self.handle_exception(exc)
  File "/home/iboon_laptop_18/AI/imagelens/face_env/lib/python3.10/site-packages/rest_framework/views.py", line 469, in handle_exception
    self.raise_uncaught_exception(exc)
  File "/home/iboon_laptop_18/AI/imagelens/face_env/lib/python3.10/site-packages/rest_framework/views.py", line 480, in raise_uncaught_exception
    raise exc
  File "/home/iboon_laptop_18/AI/imagelens/face_env/lib/python3.10/site-packages/rest_framework/views.py", line 506, in dispatch
    response = handler(request, *args, **kwargs)
  File "/home/iboon_laptop_18/Documents/imagelens/groups/view/group_views.py", line 39, in get_family_photos
    family_members = family.objects.filter(user__in=custom_group.created_by.family_members.all())
NameError: name 'family' is not defined
ERROR 2024-12-11 15:53:10,049 basehttp "GET /api/group/get-customgroup-viewset-family-member/17/ HTTP/1.1" 500 100132
ERROR 2024-12-11 15:54:36,762 log Internal Server Error: /api/group/get-customgroup-viewset-family-member/17/
Traceback (most recent call last):
  File "/home/iboon_laptop_18/AI/imagelens/face_env/lib/python3.10/site-packages/django/core/handlers/exception.py", line 55, in inner
    response = get_response(request)
  File "/home/iboon_laptop_18/AI/imagelens/face_env/lib/python3.10/site-packages/django/core/handlers/base.py", line 197, in _get_response
    response = wrapped_callback(request, *callback_args, **callback_kwargs)
  File "/home/iboon_laptop_18/AI/imagelens/face_env/lib/python3.10/site-packages/django/views/decorators/csrf.py", line 65, in _view_wrapper
    return view_func(request, *args, **kwargs)
  File "/home/iboon_laptop_18/AI/imagelens/face_env/lib/python3.10/site-packages/rest_framework/viewsets.py", line 124, in view
    return self.dispatch(request, *args, **kwargs)
  File "/home/iboon_laptop_18/AI/imagelens/face_env/lib/python3.10/site-packages/rest_framework/views.py", line 509, in dispatch
    response = self.handle_exception(exc)
  File "/home/iboon_laptop_18/AI/imagelens/face_env/lib/python3.10/site-packages/rest_framework/views.py", line 469, in handle_exception
    self.raise_uncaught_exception(exc)
  File "/home/iboon_laptop_18/AI/imagelens/face_env/lib/python3.10/site-packages/rest_framework/views.py", line 480, in raise_uncaught_exception
    raise exc
  File "/home/iboon_laptop_18/AI/imagelens/face_env/lib/python3.10/site-packages/rest_framework/views.py", line 506, in dispatch
    response = handler(request, *args, **kwargs)
  File "/home/iboon_laptop_18/Documents/imagelens/groups/view/group_views.py", line 40, in get_family_photos
    family_members = family.objects.filter(user__in=custom_group.created_by.family_members.all())
NameError: name 'family' is not defined
ERROR 2024-12-11 15:54:36,771 basehttp "GET /api/group/get-customgroup-viewset-family-member/17/ HTTP/1.1" 500 100738
ERROR 2024-12-12 15:11:44,168 log Internal Server Error: /api/get-family/
Traceback (most recent call last):
  File "/home/iboon_laptop_18/AI/imagelens/face_env/lib/python3.10/site-packages/django/db/models/fields/__init__.py", line 2123, in get_prep_value
    return int(value)
ValueError: invalid literal for int() with base 10: '/74/'

The above exception was the direct cause of the following exception:

Traceback (most recent call last):
  File "/home/iboon_laptop_18/AI/imagelens/face_env/lib/python3.10/site-packages/django/core/handlers/exception.py", line 55, in inner
    response = get_response(request)
  File "/home/iboon_laptop_18/AI/imagelens/face_env/lib/python3.10/site-packages/django/core/handlers/base.py", line 197, in _get_response
    response = wrapped_callback(request, *callback_args, **callback_kwargs)
  File "/home/iboon_laptop_18/AI/imagelens/face_env/lib/python3.10/site-packages/django/views/decorators/csrf.py", line 65, in _view_wrapper
    return view_func(request, *args, **kwargs)
  File "/home/iboon_laptop_18/AI/imagelens/face_env/lib/python3.10/site-packages/rest_framework/viewsets.py", line 124, in view
    return self.dispatch(request, *args, **kwargs)
  File "/home/iboon_laptop_18/AI/imagelens/face_env/lib/python3.10/site-packages/rest_framework/views.py", line 509, in dispatch
    response = self.handle_exception(exc)
  File "/home/iboon_laptop_18/AI/imagelens/face_env/lib/python3.10/site-packages/rest_framework/views.py", line 469, in handle_exception
    self.raise_uncaught_exception(exc)
  File "/home/iboon_laptop_18/AI/imagelens/face_env/lib/python3.10/site-packages/rest_framework/views.py", line 480, in raise_uncaught_exception
    raise exc
  File "/home/iboon_laptop_18/AI/imagelens/face_env/lib/python3.10/site-packages/rest_framework/views.py", line 506, in dispatch
    response = handler(request, *args, **kwargs)
  File "/home/iboon_laptop_18/Documents/imagelens/imagesense/view/family_view.py", line 41, in list
    queryset = self.filter_queryset(self.get_queryset())
  File "/home/iboon_laptop_18/Documents/imagelens/imagesense/view/family_view.py", line 33, in get_queryset
    user = get_user_model().objects.get(id=user_id)
  File "/home/iboon_laptop_18/AI/imagelens/face_env/lib/python3.10/site-packages/django/db/models/manager.py", line 87, in manager_method
    return getattr(self.get_queryset(), name)(*args, **kwargs)
  File "/home/iboon_laptop_18/AI/imagelens/face_env/lib/python3.10/site-packages/django/db/models/query.py", line 635, in get
    clone = self._chain() if self.query.combinator else self.filter(*args, **kwargs)
  File "/home/iboon_laptop_18/AI/imagelens/face_env/lib/python3.10/site-packages/django/db/models/query.py", line 1476, in filter
    return self._filter_or_exclude(False, args, kwargs)
  File "/home/iboon_laptop_18/AI/imagelens/face_env/lib/python3.10/site-packages/django/db/models/query.py", line 1494, in _filter_or_exclude
    clone._filter_or_exclude_inplace(negate, args, kwargs)
  File "/home/iboon_laptop_18/AI/imagelens/face_env/lib/python3.10/site-packages/django/db/models/query.py", line 1501, in _filter_or_exclude_inplace
    self._query.add_q(Q(*args, **kwargs))
  File "/home/iboon_laptop_18/AI/imagelens/face_env/lib/python3.10/site-packages/django/db/models/sql/query.py", line 1609, in add_q
    clause, _ = self._add_q(q_object, self.used_aliases)
  File "/home/iboon_laptop_18/AI/imagelens/face_env/lib/python3.10/site-packages/django/db/models/sql/query.py", line 1641, in _add_q
    child_clause, needed_inner = self.build_filter(
  File "/home/iboon_laptop_18/AI/imagelens/face_env/lib/python3.10/site-packages/django/db/models/sql/query.py", line 1555, in build_filter
    condition = self.build_lookup(lookups, col, value)
  File "/home/iboon_laptop_18/AI/imagelens/face_env/lib/python3.10/site-packages/django/db/models/sql/query.py", line 1385, in build_lookup
    lookup = lookup_class(lhs, rhs)
  File "/home/iboon_laptop_18/AI/imagelens/face_env/lib/python3.10/site-packages/django/db/models/lookups.py", line 30, in __init__
    self.rhs = self.get_prep_lookup()
  File "/home/iboon_laptop_18/AI/imagelens/face_env/lib/python3.10/site-packages/django/db/models/lookups.py", line 369, in get_prep_lookup
    return super().get_prep_lookup()
  File "/home/iboon_laptop_18/AI/imagelens/face_env/lib/python3.10/site-packages/django/db/models/lookups.py", line 88, in get_prep_lookup
    return self.lhs.output_field.get_prep_value(self.rhs)
  File "/home/iboon_laptop_18/AI/imagelens/face_env/lib/python3.10/site-packages/django/db/models/fields/__init__.py", line 2125, in get_prep_value
    raise e.__class__(
ValueError: Field 'id' expected a number but got '/74/'.
ERROR 2024-12-12 15:11:44,248 basehttp "GET /api/get-family/?user_id=/74/ HTTP/1.1" 500 174130
ERROR 2024-12-12 16:10:07,348 log Internal Server Error: /api/group/upload-group-photo/
Traceback (most recent call last):
  File "/home/iboon_laptop_18/AI/imagelens/face_env/lib/python3.10/site-packages/django/core/handlers/exception.py", line 55, in inner
    response = get_response(request)
  File "/home/iboon_laptop_18/AI/imagelens/face_env/lib/python3.10/site-packages/django/core/handlers/base.py", line 197, in _get_response
    response = wrapped_callback(request, *callback_args, **callback_kwargs)
  File "/home/iboon_laptop_18/AI/imagelens/face_env/lib/python3.10/site-packages/django/views/decorators/csrf.py", line 65, in _view_wrapper
    return view_func(request, *args, **kwargs)
  File "/home/iboon_laptop_18/AI/imagelens/face_env/lib/python3.10/site-packages/rest_framework/viewsets.py", line 124, in view
    return self.dispatch(request, *args, **kwargs)
  File "/home/iboon_laptop_18/AI/imagelens/face_env/lib/python3.10/site-packages/rest_framework/views.py", line 509, in dispatch
    response = self.handle_exception(exc)
  File "/home/iboon_laptop_18/AI/imagelens/face_env/lib/python3.10/site-packages/rest_framework/views.py", line 469, in handle_exception
    self.raise_uncaught_exception(exc)
  File "/home/iboon_laptop_18/AI/imagelens/face_env/lib/python3.10/site-packages/rest_framework/views.py", line 480, in raise_uncaught_exception
    raise exc
  File "/home/iboon_laptop_18/AI/imagelens/face_env/lib/python3.10/site-packages/rest_framework/views.py", line 506, in dispatch
    response = handler(request, *args, **kwargs)
  File "/home/iboon_laptop_18/Documents/imagelens/groups/view/upload_photo_view.py", line 218, in create
    serializer.save()
  File "/home/iboon_laptop_18/AI/imagelens/face_env/lib/python3.10/site-packages/rest_framework/serializers.py", line 208, in save
    self.instance = self.create(validated_data)
  File "/home/iboon_laptop_18/Documents/imagelens/groups/serializers/photo_upload_serializer.py", line 45, in create
    PhotoGroupImage.objects.create(
  File "/home/iboon_laptop_18/AI/imagelens/face_env/lib/python3.10/site-packages/django/db/models/manager.py", line 87, in manager_method
    return getattr(self.get_queryset(), name)(*args, **kwargs)
  File "/home/iboon_laptop_18/AI/imagelens/face_env/lib/python3.10/site-packages/django/db/models/query.py", line 679, in create
    obj.save(force_insert=True, using=self.db)
  File "/home/iboon_laptop_18/AI/imagelens/face_env/lib/python3.10/site-packages/django/db/models/base.py", line 891, in save
    self.save_base(
  File "/home/iboon_laptop_18/AI/imagelens/face_env/lib/python3.10/site-packages/django/db/models/base.py", line 997, in save_base
    updated = self._save_table(
  File "/home/iboon_laptop_18/AI/imagelens/face_env/lib/python3.10/site-packages/django/db/models/base.py", line 1160, in _save_table
    results = self._do_insert(
  File "/home/iboon_laptop_18/AI/imagelens/face_env/lib/python3.10/site-packages/django/db/models/base.py", line 1201, in _do_insert
    return manager._insert(
  File "/home/iboon_laptop_18/AI/imagelens/face_env/lib/python3.10/site-packages/django/db/models/manager.py", line 87, in manager_method
    return getattr(self.get_queryset(), name)(*args, **kwargs)
  File "/home/iboon_laptop_18/AI/imagelens/face_env/lib/python3.10/site-packages/django/db/models/query.py", line 1847, in _insert
    return query.get_compiler(using=using).execute_sql(returning_fields)
  File "/home/iboon_laptop_18/AI/imagelens/face_env/lib/python3.10/site-packages/django/db/models/sql/compiler.py", line 1835, in execute_sql
    for sql, params in self.as_sql():
  File "/home/iboon_laptop_18/AI/imagelens/face_env/lib/python3.10/site-packages/django/db/models/sql/compiler.py", line 1758, in as_sql
    value_rows = [
  File "/home/iboon_laptop_18/AI/imagelens/face_env/lib/python3.10/site-packages/django/db/models/sql/compiler.py", line 1759, in <listcomp>
    [
  File "/home/iboon_laptop_18/AI/imagelens/face_env/lib/python3.10/site-packages/django/db/models/sql/compiler.py", line 1760, in <listcomp>
    self.prepare_value(field, self.pre_save_val(field, obj))
  File "/home/iboon_laptop_18/AI/imagelens/face_env/lib/python3.10/site-packages/django/db/models/sql/compiler.py", line 1708, in pre_save_val
    return field.pre_save(obj, add=True)
  File "/home/iboon_laptop_18/AI/imagelens/face_env/lib/python3.10/site-packages/django/db/models/fields/files.py", line 338, in pre_save
    file.save(file.name, file.file, save=False)
  File "/home/iboon_laptop_18/AI/imagelens/face_env/lib/python3.10/site-packages/django/db/models/fields/files.py", line 98, in save
    name = self.field.generate_filename(self.instance, name)
  File "/home/iboon_laptop_18/AI/imagelens/face_env/lib/python3.10/site-packages/django/db/models/fields/files.py", line 353, in generate_filename
    filename = self.upload_to(instance, filename)
  File "/home/iboon_laptop_18/Documents/imagelens/groups/model/group.py", line 57, in user_image_upload_path
    return os.path.join(f'photos/{user_email}/{group_name}', filename)
UnboundLocalError: local variable 'user_email' referenced before assignment
ERROR 2024-12-12 16:10:07,362 basehttp "POST /api/group/upload-group-photo/ HTTP/1.1" 500 197765
ERROR 2024-12-12 19:19:20,839 log Internal Server Error: /api/analyze-face-image/
ERROR 2024-12-12 19:19:20,840 basehttp "POST /api/analyze-face-image/?group=15 HTTP/1.1" 500 95
ERROR 2024-12-12 23:03:02,609 log Internal Server Error: /api/analyze-face-image/
ERROR 2024-12-12 23:03:02,611 basehttp "POST /api/analyze-face-image/ HTTP/1.1" 500 95
